<?xml version="1.0"?>
<robot name="six_dof_arm" xmlns:xacro="http://www.ros.org/wiki/xacro">

<link name="base_link"/>

<!-- Joint 1 -->
<joint name="joint1" type="revolute">
  <parent link="base_link"/>
  <child link="link1"/>
  <origin xyz="0 0 0.1" rpy="0 0 0"/>
  <axis xyz="0 0 1"/>
</joint>

<link name="link1"/>

<!-- Joint 2 -->
<joint name="joint2" type="revolute">
  <parent link="link1"/>
  <child link="link2"/>
  <origin xyz="0 0 0.2" rpy="0 0 0"/>
  <axis xyz="0 1 0"/>
</joint>

<link name="link2"/>

<!-- Joint 3 -->
<joint name="joint3" type="revolute">
  <parent link="link2"/>
  <child link="link3"/>
  <origin xyz="0 0 0.2" rpy="0 0 0"/>
  <axis xyz="0 1 0"/>
</joint>

<link name="link3"/>

<!-- Joint 4 -->
<joint name="joint4" type="revolute">
  <parent link="link3"/>
  <child link="link4"/>
  <origin xyz="0 0 0.2" rpy="0 0 0"/>
  <axis xyz="1 0 0"/>
</joint>

<link name="link4"/>

<!-- Joint 5 -->
<joint name="joint5" type="revolute">
  <parent link="link4"/>
  <child link="link5"/>
  <origin xyz="0 0 0.15" rpy="0 0 0"/>
  <axis xyz="0 1 0"/>
</joint>

<link name="link5"/>

<!-- End Effector -->
<joint name="joint6" type="revolute">
  <parent link="link5"/>
  <child link="ee_link"/>
  <origin xyz="0 0 0.1" rpy="0 0 0"/>
  <axis xyz="0 0 1"/>
</joint>

<link name="ee_link"/>

</robot>
